<?xml version="1.0" ?>
<sdf version="1.9">
  <world name="car_world">
    <physics name="1ms" type="ignored">
      <max_step_size>0.001</max_step_size>
      <real_time_factor>1.0</real_time_factor>
    </physics>

    <!-- Tunnel -->
    <include>
      <uri>model://test_tunnel</uri>
      <pose>5.8393 -20.2138 0.9081 0.1180 0 2.3584</pose>
    </include>

    <!-- Core plugins -->
    <plugin filename="ignition-gazebo-sensors-system"
            name="ignition::gazebo::systems::Sensors"/>
    <plugin filename="libignition-gazebo-physics-system.so"
            name="ignition::gazebo::systems::Physics"/>
    <plugin filename="libignition-gazebo-user-commands-system.so"
            name="ignition::gazebo::systems::UserCommands"/>
    <plugin filename="libignition-gazebo-scene-broadcaster-system.so"
            name="ignition::gazebo::systems::SceneBroadcaster"/>

    <!-- Sunlight -->
    <light type="directional" name="sun">
      <cast_shadows>true</cast_shadows>
      <pose>0 0 10 0 0 0</pose>
      <diffuse>0.8 0.8 0.8 1</diffuse>
      <specular>0.2 0.2 0.2 1</specular>
      <attenuation>
        <range>1000</range>
        <constant>0.9</constant>
        <linear>0.01</linear>
        <quadratic>0.001</quadratic>
      </attenuation>
      <direction>-0.5 0.1 -0.9</direction>
    </light>

    <!-- Ground plane -->
    <model name="ground_plane">
      <static>true</static>
      <link name="link">
        <collision name="collision">
          <geometry>
            <plane><normal>0 0 1</normal></plane>
          </geometry>
        </collision>
        <visual name="visual">
          <geometry>
            <plane>
              <normal>0 0 1</normal>
              <size>100 100</size>
            </plane>
          </geometry>
          <material>
            <ambient>0.8 0.8 0.8 1</ambient>
            <diffuse>0.8 0.8 0.8 1</diffuse>
            <specular>0.8 0.8 0.8 1</specular>
          </material>
        </visual>
      </link>
    </model>

    <!-- Extra objects -->
    <include>
      <uri>model://Falling Rock 1</uri>
      <pose>10 0 0.2 0 0 1.57</pose>
    </include>

    <include>
      <uri>https://fuel.gazebosim.org/1.0/iche033/models/Water Bottle</uri>
      <pose>14 2 0.2 0 0 1.57</pose>
    </include>

    <!-- Robot -->
    <model name="vehicle_blue" canonical_link="chassis">
      <pose relative_to="world">0 0 0 0 0 0</pose>

      <!-- Chassis -->
      <link name="chassis">
        <pose relative_to="__model__">0.5 0 0.4 0 0 0</pose>
        <inertial>
          <mass>3.14395</mass>
          <inertia>
            <ixx>0.095329</ixx>
            <ixy>0</ixy>
            <ixz>0</ixz>
            <iyy>0.381317</iyy>
            <iyz>0</iyz>
            <izz>0.476646</izz>
          </inertia>
        </inertial>
        <visual name="visual">
          <geometry><box><size>2.0 1.0 0.5</size></box></geometry>
          <material>
            <ambient>0.5 0.5 0.5 1</ambient>
            <diffuse>0.5 0.5 0.5 1</diffuse>
            <specular>0.1 0.1 0.1 1</specular>
          </material>
        </visual>
        <collision name="collision">
          <geometry><box><size>2.0 1.0 0.5</size></box></geometry>
        </collision>
      </link>

      <!-- Camera -->
      <link name="camera_link">
        <pose>0 0 1 0 0 0</pose>
        <sensor name="camera_sensor" type="camera">
          <pose>0 0 0 0 0 0</pose>
          <camera>
            <horizontal_fov>1.047</horizontal_fov>
            <image>
              <width>640</width>
              <height>480</height>
              <format>R8G8B8</format>
            </image>
            <clip>
              <near>0.1</near>
              <far>100</far>
            </clip>
          </camera>
          <always_on>1</always_on>
          <update_rate>30</update_rate>
          <visualize>true</visualize>
          <topic>camera</topic>
        </sensor>
      </link>
      <joint name="chassis_camera_joint" type="fixed">
        <parent>chassis</parent>
        <child>camera_link</child>
      </joint>

      <!-- Wheels (all four) -->
      <link name="left_wheel"><pose relative_to="chassis">-0.5 0.6 0 -1.5707 0 0</pose></link>
      <link name="right_wheel"><pose relative_to="chassis">-0.5 -0.6 0 -1.5707 0 0</pose></link>
      <link name="left_wheel2"><pose relative_to="chassis">0.5 0.6 0 -1.5707 0 0</pose></link>
      <link name="right_wheel2"><pose relative_to="chassis">0.5 -0.6 0 -1.5707 0 0</pose></link>

      <!-- Wheel joints -->
      <joint name="left_wheel_joint" type="revolute">
        <parent>chassis</parent><child>left_wheel</child>
        <axis><xyz>0 1 0</xyz></axis>
      </joint>
      <joint name="right_wheel_joint" type="revolute">
        <parent>chassis</parent><child>right_wheel</child>
        <axis><xyz>0 1 0</xyz></axis>
      </joint>
      <joint name="left_wheel_joint2" type="revolute">
        <parent>chassis</parent><child>left_wheel2</child>
        <axis><xyz>0 1 0</xyz></axis>
      </joint>
      <joint name="right_wheel_joint2" type="revolute">
        <parent>chassis</parent><child>right_wheel2</child>
        <axis><xyz>0 1 0</xyz></axis>
      </joint>

      <!-- Diff drive -->
      <plugin filename="libignition-gazebo-diff-drive-system.so"
              name="ignition::gazebo::systems::DiffDrive">
        <left_joint>left_wheel_joint</left_joint>
        <left_joint>left_wheel_joint2</left_joint>
        <right_joint>right_wheel_joint</right_joint>
        <right_joint>right_wheel_joint2</right_joint>
        <wheel_separation>1.2</wheel_separation>
        <wheel_radius>0.4</wheel_radius>
        <odom_topic>odom</odom_topic>
        <odom_frame>odom</odom_frame>
        <robot_base_frame>chassis</robot_base_frame>
        <odom_publish_frequency>50</odom_publish_frequency>
        <publish_wheel_joint_states>true</publish_wheel_joint_states>
        <wheel_joint_state_topic>joint_states</wheel_joint_state_topic>
        <topic>cmd_vel</topic>
      </plugin>

      <!-- Keyboard teleop -->
      <plugin filename="libignition-gazebo-triggered-publisher-system.so"
              name="ignition::gazebo::systems::TriggeredPublisher">
        <input type="ignition.msgs.Int32" topic="/keyboard/keypress">
          <match field="data">87</match>
        </input>
        <output type="ignition.msgs.Twist" topic="/cmd_vel">
          linear: {x: 3}, angular: {z: 0.0}
        </output>
      </plugin>

      <plugin filename="libignition-gazebo-triggered-publisher-system.so"
              name="ignition::gazebo::systems::TriggeredPublisher">
        <input type="ignition.msgs.Int32" topic="/keyboard/keypress">
          <match field="data">83</match>
        </input>
        <output type="ignition.msgs.Twist" topic="/cmd_vel">
          linear: {x:-3}, angular: {z: 0.0}
        </output>
      </plugin>

      <plugin filename="libignition-gazebo-triggered-publisher-system.so"
              name="ignition::gazebo::systems::TriggeredPublisher">
        <input type="ignition.msgs.Int32" topic="/keyboard/keypress">
          <match field="data">65</match>
        </input>
        <output type="ignition.msgs.Twist" topic="/cmd_vel">
          linear: {x: 3}, angular: {z: 0.5}
        </output>
      </plugin>

      <plugin filename="libignition-gazebo-triggered-publisher-system.so"
              name="ignition::gazebo::systems::TriggeredPublisher">
        <input type="ignition.msgs.Int32" topic="/keyboard/keypress">
          <match field="data">68</match>
        </input>
        <output type="ignition.msgs.Twist" topic="/cmd_vel">
          linear: {x: 3}, angular: {z: -0.5}
        </output>
      </plugin>
    </model>
  </world>
</sdf>
